Workbook
Name Slicer_INVOICE_DATE: #N/A

Sheet 1-SQLs
A1: A- TOTAL SALES PER MONTH | C1: SELECT TO_CHAR(invoice_date, 'YYYY-MM') AS month, SUM(quantity * unit_price) AS total_sales FROM sales_transactions GROUP BY TO_CHAR(invoice_date, 'YYYY-MM') ORDER BY month;
A2: B- SALES BY PRODUCT CATEGORY | C2: SELECT description, SUM(quantity * unit_price) AS total_sales FROM sales_transactions GROUP BY description ORDER BY total_sales DESC;
A3: C-NUMBER OF TRANSACTIONS PER CUSTOMER | C3: SELECT customer_id, COUNT(*) AS transaction_count FROM sales_transactions GROUP BY customer_id ORDER BY transaction_count DESC;

Sheet MAIN DATASET
A1: TRANSACTION_ID | B1: INVOICE_NO | C1: STOCK CODE | D1: DESCRIPTION/CATEGORY | E1: QUANTITY | F1: INVOICE_DATE | G1: UNIT_PRICE | H1: CUSTOMER_ID | I1: COUNTRY | J1: TIMESTAMP | K1: TOTAL
A2: 1 | B2: 536382 | C2: 85123A | D2: WHITE HANGING HEART T-LIGHT HOLDER | E2: 100 | F2: 45927 | G2: 2.55 | H2: 17850 | I2: United Kingdom | J2: 45920.518 | K2: 255
A3: 2 | B3: 536383 | C3: 71053 | D3: WHITE METAL LANTERN | E3: 6 | F3: 45925 | G3: 3.39 | H3: 17850 | I3: United Kingdom | J3: 45920.518 | K3: 20.34
A4: 3 | B4: 536384 | C4: 84406B | D4: CREAM CUPID HEARTS COAT HANGER | E4: 8 | F4: 45925 | G4: 2.75 | H4: 17850 | I4: United Kingdom | J4: 45920.518 | K4: 22
A5: 4 | B5: 536365 | C5: 84029G | D5: KNITTED UNION FLAG HOT WATER BOTTLE | E5: 6 | F5: 40513 | G5: 3.39 | H5: 17850 | I5: United Kingdom | J5: 45920.518 | K5: 20.34
A6: 5 | B6: 536382 | C6: 84029E | D6: RED WOOLLY HOTTIE WHITE HEART. | E6: 5 | F6: 45924 | G6: 3.39 | H6: 17850 | I6: United Kingdom | J6: 45920.518 | K6: 16.95
A7: 6 | B7: 536365 | C7: 22752 | D7: SET 7 BABUSHKA NESTING BOXES | E7: 2 | F7: 40513 | G7: 7.65 | H7: 17850 | I7: United Kingdom | J7: 45920.518 | K7: 15.3
A8: 7 | B8: 536365 | C8: 21730 | D8: GLASS STAR FROSTED T-LIGHT HOLDER | E8: 6 | F8: 40513 | G8: 4.25 | H8: 17850 | I8: United Kingdom | J8: 45920.518 | K8: 25.5
A9: 8 | B9: 536366 | C9: 22633 | D9: HAND WARMER UNION JACK | E9: 6 | F9: 40513 | G9: 1.85 | H9: 17850 | I9: United Kingdom | J9: 45920.518 | K9: 11.1
A10: 9 | B10: 536366 | C10: 22632 | D10: HAND WARMER RED POLKA DOT | E10: 6 | F10: 40513 | G10: 1.85 | H10: 17850 | I10: United Kingdom | J10: 45920.518 | K10: 11.1
A11: 10 | B11: 536368 | C11: 22960 | D11: JAM MAKING SET WITH JARS | E11: 6 | F11: 40513 | G11: 4.25 | H11: 13047 | I11: United Kingdom | J11: 45920.518 | K11: 25.5
A12: 11 | B12: 536368 | C12: 22913 | D12: RED COAT RACK PARIS FASHION | E12: 3 | F12: 40513 | G12: 4.95 | H12: 13047 | I12: United Kingdom | J12: 45920.518 | K12: 14.85
A13: 12 | B13: 536368 | C13: 22912 | D13: YELLOW COAT RACK PARIS FASHION | E13: 3 | F13: 40513 | G13: 4.95 | H13: 13047 | I13: United Kingdom | J13: 45920.518 | K13: 14.85
A14: 13 | B14: 536368 | C14: 22914 | D14: BLUE COAT RACK PARIS FASHION | E14: 3 | F14: 40513 | G14: 4.95 | H14: 13047 | I14: United Kingdom | J14: 45920.518 | K14: 14.85
A15: 14 | B15: 536367 | C15: 84879 | D15: ASSORTED COLOUR BIRD ORNAMENT | E15: 32 | F15: 40513 | G15: 1.69 | H15: 13047 | I15: United Kingdom | J15: 45920.518 | K15: 54.08
A16: 15 | B16: 536367 | C16: 22745 | D16: POPPY'S PLAYHOUSE BEDROOM | E16: 6 | F16: 40513 | G16: 2.1 | H16: 13047 | I16: United Kingdom | J16: 45920.518 | K16: 12.6
A17: 16 | B17: 536367 | C17: 22748 | D17: POPPY'S PLAYHOUSE KITCHEN | E17: 6 | F17: 40513 | G17: 2.1 | H17: 13047 | I17: United Kingdom | J17: 45920.518 | K17: 12.6
A18: 17 | B18: 536367 | C18: 22749 | D18: FELTCRAFT PRINCESS CHARLOTTE DOLL | E18: 8 | F18: 40513 | G18: 3.75 | H18: 13047 | I18: United Kingdom | J18: 45920.518 | K18: 30
... A46: 45 | B46: 536370 | C46: 22492 | D46: MINI PAINT SET VINTAGE | E46: 36 | F46: 40513 | G46: 0.65 | H46: 12583 | I46: France | J46: 45920.518 | K46: 23.4
A47: 46 | B47: 536370 | C47: POST | D47: POSTAGE | E47: 3 | F47: 40513 | G47: 18 | H47: 12583 | I47: France | J47: 45920.518 | K47: 54
A48: 47 | B48: 536371 | C48: 22086 | D48: PAPER CHAIN KIT 50'S CHRISTMAS | E48: 80 | F48: 40513 | G48: 2.55 | H48: 13748 | I48: United Kingdom | J48: 45920.518 | K48: 204
A49: 48 | B49: 536372 | C49: 22632 | D49: HAND WARMER RED POLKA DOT | E49: 6 | F49: 40513 | G49: 1.85 | H49: 17850 | I49: United Kingdom | J49: 45920.518 | K49: 11.1
A50: 49 | B50: 536372 | C50: 22633 | D50: HAND WARMER UNION JACK | E50: 6 | F50: 40513 | G50: 1.85 | H50: 17850 | I50: United Kingdom | J50: 45920.518 | K50: 11.1
A51: 50 | B51: 536373 | C51: 85123A | D51: WHITE HANGING HEART T-LIGHT HOLDER | E51: 6 | F51: 40513 | G51: 2.55 | H51: 17850 | I51: United Kingdom | J51: 45920.518 | K51: 15.3
A52: 51 | B52: 536373 | C52: 71053 | D52: WHITE METAL LANTERN | E52: 6 | F52: 40513 | G52: 3.39 | H52: 17850 | I52: United Kingdom | J52: 45920.518 | K52: 20.34
A53: 52 | B53: 536373 | C53: 84406B | D53: CREAM CUPID HEARTS COAT HANGER | E53: 8 | F53: 40513 | G53: 2.75 | H53: 17850 | I53: United Kingdom | J53: 45920.518 | K53: 22
A54: 53 | B54: 536373 | C54: 20679 | D54: EDWARDIAN PARASOL RED | E54: 6 | F54: 40513 | G54: 4.95 | H54: 17850 | I54: United Kingdom | J54: 45920.518 | K54: 29.7
A55: 54 | B55: 536373 | C55: 37370 | D55: RETRO COFFEE MUGS ASSORTED | E55: 6 | F55: 40513 | G55: 1.06 | H55: 17850 | I55: United Kingdom | J55: 45920.518 | K55: 6.36
A56: 55 | B56: 536373 | C56: 21871 | D56: SAVE THE PLANET MUG | E56: 6 | F56: 40513 | G56: 1.06 | H56: 17850 | I56: United Kingdom | J56: 45920.518 | K56: 6.36
A57: 56 | B57: 536373 | C57: 21071 | D57: VINTAGE BILLBOARD DRINK ME MUG | E57: 6 | F57: 40513 | G57: 1.06 | H57: 17850 | I57: United Kingdom | J57: 45920.518 | K57: 6.36
A58: 57 | B58: 536373 | C58: 21068 | D58: VINTAGE BILLBOARD LOVE/HATE MUG | E58: 6 | F58: 40513 | G58: 1.06 | H58: 17850 | I58: United Kingdom | J58: 45920.518 | K58: 6.36
A59: 58 | B59: 536373 | C59: 82483 | D59: WOOD 2 DRAWER CABINET WHITE FINISH | E59: 2 | F59: 40513 | G59: 4.95 | H59: 17850 | I59: United Kingdom | J59: 45920.518 | K59: 9.9
A60: 59 | B60: 536373 | C60: 82486 | D60: WOOD S/3 CABINET ANT WHITE FINISH | E60: 4 | F60: 40513 | G60: 6.95 | H60: 17850 | I60: United Kingdom | J60: 45920.518 | K60: 27.8
A61: 60 | B61: 536373 | C61: 82482 | D61: WOODEN PICTURE FRAME WHITE FINISH | E61: 6 | F61: 40513 | G61: 2.1 | H61: 17850 | I61: United Kingdom | J61: 45920.518 | K61: 12.6
A62: 61 | B62: 536373 | C62: 82494L | D62: WOODEN FRAME ANTIQUE WHITE | E62: 6 | F62: 40513 | G62: 2.55 | H62: 17850 | I62: United Kingdom | J62: 45920.518 | K62: 15.3
A63: 62 | B63: 536373 | C63: 84029G | D63: KNITTED UNION FLAG HOT WATER BOTTLE | E63: 6 | F63: 40513 | G63: 3.39 | H63: 17850 | I63: United Kingdom | J63: 45920.518 | K63: 20.34
A64: 63 | B64: 536373 | C64: 84029E | D64: RED WOOLLY HOTTIE WHITE HEART. | E64: 6 | F64: 40513 | G64: 3.39 | H64: 17850 | I64: United Kingdom | J64: 45920.518 | K64: 20.34
A65: 64 | B65: 536373 | C65: 22752 | D65: SET 7 BABUSHKA NESTING BOXES | E65: 2 | F65: 40513 | G65: 7.65 | H65: 17850 | I65: United Kingdom | J65: 45920.518 | K65: 15.3
A66: 65 | B66: 536373 | C66: 21730 | D66: GLASS STAR FROSTED T-LIGHT HOLDER | E66: 6 | F66: 40513 | G66: 4.25 | H66: 17850 | I66: United Kingdom | J66: 45920.518 | K66: 25.5
A67: 66 | B67: 536374 | C67: 21258 | D67: VICTORIAN SEWING BOX LARGE | E67: 32 | F67: 40513 | G67: 10.95 | H67: 15100 | I67: United Kingdom | J67: 45920.518 | K67: 350.4
...

Sheet Historical Data
A1: HISTORICAL DATA
A2: Year | B2: Revenue | C2: COGS | D2: Operating Expenses | E2: Net Income
A3: 2010 | B3: ='MAIN DATASET'!L107 -> 3391.46 | C3: =B3*'Inputs & Assumptions '!G3 -> 2034.876 | D3: =B3*'Inputs & Assumptions '!G4 -> 678.292 | E3: =((B3-C3-D3)*(1-'Inputs & Assumptions '!G5)) -> 474.8044
A4: 2025 | B4: ='MAIN DATASET'!L116 -> 25800.9 | C4: =B4*'Inputs & Assumptions '!G4 -> 5160.18 | D4: =B4*'Inputs & Assumptions '!G5 -> 7740.27 | E4: =((B4-C4-D4)*(1-'Inputs & Assumptions '!G6)) -> 12900.45

Sheet Inputs & Assumptions 
A1: INPUTS & ASSUMPTIONS | F1: PERCENTAGE | G1: DECIMAL
A2: Sales Growth Rate | F2: 0.1 | G2: =F2 -> 0.1
A3: (Cost Of Goods) COGS % of Revenue | F3: 0.6 | G3: =F3 -> 0.6
A4: Operating Expense % of Revenue | F4: 0.2 | G4: =F4 -> 0.2
A5: Tax Rate | F5: 0.3 | G5: =F5 -> 0.3

Sheet Current Year Forecast
A1: YEAR | B1: REVENUE | C1: COGS | D1: OPERATING EXPENSES | E1: EBIT | F1: TAX | G1: NET INCOME | H1: GROSS PROFIT
A2: 2011 | B2: ='Historical Data'!B3 * (1+'Inputs & Assumptions '!G2) -> 3730.606 | C2: =B2*'Inputs & Assumptions '!G3 -> 2238.3636 | D2: =B2*'Inputs & Assumptions '!G4 -> 746.1212 | E2: =B2-C2-D2 -> 746.1212 | F2: =E2*'Inputs & Assumptions '!G5 -> 223.83636 | G2: =E2-F2 -> 522.28484 | H2: =B2 - C2 -> 1492.2424
A3: 2012 | B3: =B2*(1+'Inputs & Assumptions '!G2) -> 4103.6666 | C3: =B3*'Inputs & Assumptions '!G3 -> 2462.2 | D3: =B3*'Inputs & Assumptions '!G4 -> 820.73332 | E3: =B3-C3-D3 -> 820.73332 | F3: =E3*'Inputs & Assumptions '!G5 -> 246.22 | G3: =E3-F3 -> 574.51332 | H3: =B3 - C3 -> 1641.4666
A4: 2013 | B4: =B3*(1+'Inputs & Assumptions '!G2) -> 4514.0333 | C4: =B4*'Inputs & Assumptions '!G3 -> 2708.42 | D4: =B4*'Inputs & Assumptions '!G4 -> 902.80665 | E4: =B4-C4-D4 -> 902.80665 | F4: =E4*'Inputs & Assumptions '!G5 -> 270.842 | G4: =E4-F4 -> 631.96466 | H4: =B4 - C4 -> 1805.6133
A5: 2014 | B5: =B4*(1+'Inputs & Assumptions '!G2) -> 4965.4366 | C5: =B5*'Inputs & Assumptions '!G3 -> 2979.262 | D5: =B5*'Inputs & Assumptions '!G4 -> 993.08732 | E5: =B5-C5-D5 -> 993.08732 | F5: =E5*'Inputs & Assumptions '!G5 -> 297.9262 | G5: =E5-F5 -> 695.16112 | H5: =B5 - C5 -> 1986.1746
A11: YEAR | B11: REVENUE | C11: COGS | D11: OPERATING EXPENSES | E11: EBIT | F11: TAX | G11: NET INCOME | H11: GROSS PROFIT
A12: 2026 | B12: ='Historical Data'!B4*(1+'Inputs & Assumptions '!G2) -> 28380.99 | C12: =B12*'Inputs & Assumptions '!G3 -> 17028.594 | D12: =B12*'Inputs & Assumptions '!G4 -> 5676.198 | E12: =B12-C12-D12 -> 5676.198 | F12: =E12*'Inputs & Assumptions '!G5 -> 1702.8594 | G12: =E12-F12 -> 3973.3386 | H12: =B12-C12 -> 11352.396
A13: =A12+1 -> 2027 | B13: =B12*(1+'Inputs & Assumptions '!G2) -> 31219.089 | C13: =B13*'Inputs & Assumptions '!G3 -> 18731.453 | D13: =B13*'Inputs & Assumptions '!G4 -> 6243.8178 | E13: =B13-C13-D13 -> 6243.8178 | F13: =E13*'Inputs & Assumptions '!G5 -> 1873.1453 | G13: =E13-F13 -> 4370.6725 | H13: =B13-C13 -> 12487.636
A14: =A13+1 -> 2028 | B14: =B13*(1+'Inputs & Assumptions '!G2) -> 34340.998 | C14: =B14*'Inputs & Assumptions '!G3 -> 20604.599 | D14: =B14*'Inputs & Assumptions '!G4 -> 6868.1996 | E14: =B14-C14-D14 -> 6868.1996 | F14: =E14*'Inputs & Assumptions '!G5 -> 2060.4599 | G14: =E14-F14 -> 4807.7397 | H14: =B14-C14 -> 13736.399
A15: =A14+1 -> 2029 | B15: =B14*(1+'Inputs & Assumptions '!G2) -> 37775.098 | C15: =B15*'Inputs & Assumptions '!G3 -> 22665.059 | D15: =B15*'Inputs & Assumptions '!G4 -> 7555.0195 | E15: =B15-C15-D15 -> 7555.0195 | F15: =E15*'Inputs & Assumptions '!G5 -> 2266.5059 | G15: =E15-F15 -> 5288.5137 | H15: =B15-C15 -> 15110.039

Sheet Dashboard
A2: SUMMARY
A3: Year | B3: Revenue | C3: Net Income | D3: GROSS PROFIT
A4: ='Current Year Forecast'!A2 -> 2011 | B4: ='Current Year Forecast'!B2 -> 3730.606 | C4: ='Current Year Forecast'!G2 -> 522.28484 | D4: ='Current Year Forecast'!H2 -> 1492.2424
A5: ='Current Year Forecast'!A3 -> 2012 | B5: ='Current Year Forecast'!B3 -> 4103.6666 | C5: ='Current Year Forecast'!G3 -> 574.51332 | D5: ='Current Year Forecast'!H3 -> 1641.4666
A6: ='Current Year Forecast'!A4 -> 2013 | B6: ='Current Year Forecast'!B4 -> 4514.0333 | C6: ='Current Year Forecast'!G4 -> 631.96466 | D6: ='Current Year Forecast'!H4 -> 1805.6133
A7: ='Current Year Forecast'!A5 -> 2014 | B7: ='Current Year Forecast'!B5 -> 4965.4366 | C7: ='Current Year Forecast'!G5 -> 695.16112 | D7: ='Current Year Forecast'!H5 -> 1986.1746
A9: ='Current Year Forecast'!A12 -> 2026 | B9: ='Current Year Forecast'!B12 -> 28380.99 | C9: ='Current Year Forecast'!G12 -> 3973.3386 | D9: ='Current Year Forecast'!H12 -> 11352.396
A10: ='Current Year Forecast'!A13 -> 2027 | B10: ='Current Year Forecast'!B13 -> 31219.089 | C10: ='Current Year Forecast'!G13 -> 4370.6725 | D10: ='Current Year Forecast'!H13 -> 12487.636
A11: ='Current Year Forecast'!A14 -> 2028 | B11: ='Current Year Forecast'!B14 -> 34340.998 | C11: ='Current Year Forecast'!G14 -> 4807.7397 | D11: ='Current Year Forecast'!H14 -> 13736.399
A12: ='Current Year Forecast'!A15 -> 2029 | B12: ='Current Year Forecast'!B15 -> 37775.098 | C12: ='Current Year Forecast'!G15 -> 5288.5137 | D12: ='Current Year Forecast'!H15 -> 15110.039

Sheet Best Sellers
A1: Row Labels | B1: Sum of TOTAL
A2: WHITE HANGING HEART T-LIGHT HOLDER | B2: 26086.5
A3: VICTORIAN SEWING BOX LARGE | B3: 350.4
A4: PAPER CHAIN KIT 50'S CHRISTMAS | B4: 215.8
A5: HOT WATER BOTTLE TEA AND SYMPATHY | B5: 165.6
A6: RED HANGING HEART T-LIGHT HOLDER | B6: 163.2
A7: RETROSPOT TEA SET CERAMIC 11 PC | B7: 97.75
A8: ALARM CLOCK BAKELIKE RED | B8: 90
A9: ALARM CLOCK BAKELIKE PINK | B9: 90
A10: GLASS STAR FROSTED T-LIGHT HOLDER | B10: 76.5
A11: SET 2 TEA TOWELS I LOVE LONDON | B11: 70.8
A12: ROUND SNACK BOXES SET OF4 WOODLAND | B12: 70.8
A13: CREAM CUPID HEARTS COAT HANGER | B13: 66
... A80: Grand Total | B80: 29192.36

Sheet Projected Profit growth
A1: Year | B1: Net Income | C1: Profit Growth
A2: =Dashboard!A4 -> 2011 | B2: =Dashboard!C4 -> 522.28484 | C2: =(B3 - B2) / B2 -> 0.1
A3: =Dashboard!A5 -> 2012 | B3: =Dashboard!C5 -> 574.51332 | C3: =(B4 - B3) / B3 -> 0.1
A4: =Dashboard!A6 -> 2013 | B4: =Dashboard!C6 -> 631.96466 | C4: =(B5 - B4) / B4 -> 0.1
A5: =Dashboard!A7 -> 2014 | B5: =Dashboard!C7 -> 695.16112
A7: =Dashboard!A9 -> 2026 | B7: =Dashboard!C9 -> 3973.3386 | C7: =(B8 - B7) / B7 -> 0.1
A8: =Dashboard!A10 -> 2027 | B8: =Dashboard!C10 -> 4370.6725 | C8: =(B9 - B8) / B8 -> 0.1
A9: =Dashboard!A11 -> 2028 | B9: =Dashboard!C11 -> 4807.7397 | C9: =(B10 - B9) / B9 -> 0.1
A10: =Dashboard!A12 -> 2029 | B10: =Dashboard!C12 -> 5288.5137

Sheet Customer Frequency
A3: Row Labels | B3: Count of INVOICE_NO
A4: 17850 | B4: 41
A5: 12583 | B5: 20
A6: 13047 | B6: 17
A7: 15311 | B7: 17
A8: 15291 | B8: 2
A9: 14688 | B9: 2
A10: 17809 | B10: 1
A11: 13748 | B11: 1
A12: 15100 | B12: 1
A13: Grand Total | B13: 102
